Workbook

Sheet project information
A3: Informations projet
A4: project name | B4: PrestaShop Demo – Front Office (https://demo.prestashop.com/#/en/front)
A5: delivery date
A6: test design date | B6: 46316
A7: designed by | B7: Jaber El Abdellaoui (étudiant GOMYCODE)
A8: developper | B8: PrestaShop SA (éditeur de la solution testée, instance de démonstration)
A9: browsers | B9: Google Chrome
A10: android version | B10: N/A
A11: ios version | B11: N/A
A12: country | B12: Maroc
A13: pc | B13: Hp
A14: linux environment | B14: N/A
A15: windows version | B15: Windows 11 (64 bits)

Sheet Matrice de traçabilité
A1: Matrice de traçabilité – Campagne de tests fonctionnels PrestaShop Demo (front office)
A2: compagne | B2: Suite | C2: ID test | D2: titre de test | E2: type de test | F2: précondition | G2: N° d'étape | H2: Etapes | I2: Résultat attendu | J2: résultat obtenu | K2: statut | L2: ID exigence | M2: Bug ID | N2: Commentaires / Preuves | P2: Légende des statuts
A3: Campagne 1 – Tests fonctionnels front office PrestaShop Demo | B3: A. Inscription & authentification | C3: TC-01 | D3: Création d'un compte client valide | E3: Positif | F3: Utilisateur non connecté. Boutique de démo ouverte (front office, langue EN). Email de test jamais utilisé. | G3: 1 | H3: Cliquer sur « Sign in » dans l'en-tête. | I3: La page d'authentification s'affiche. | J3: La page « Sign in » s'affiche (champs Email*, Password*, bouton « Sign in », lien « Forgot your password? »). | K3: OK | L3: REQ-01 | N3: Exécuté le 21/10/2026 – instance colorful-flock.demo.prestashop.com – Chrome 155 / Windows 11. URL : /login?back=… | P3: OK | Q3: PASS – comportement conforme au résultat attendu
C4: TC-01 | G4: 2 | H4: Cliquer sur « No account? Create one here ». | I4: Le formulaire « Create an account » s'affiche ; les champs obligatoires sont signalés. | J4: Le formulaire « Create an account » s'affiche ; First name, Last name, Email, Password et les 2 cases obligatoires sont marqués « * ». | K4: OK | L4: REQ-01 | N4: Exécuté le 21/10/2026 – instance colorful-flock.demo.prestashop.com – Chrome 155 / Windows 11. URL : /registration. Libellé réel du lien : « No account? » + « Create your account » (cas de test à mettre à jour). | P4: KO | Q4: FAIL – écart constaté ; un Bug ID doit être saisi (col. M)
C5: TC-01 | G5: 3 | H5: Saisir : Social title = Mr ; First name = Test ; Last name = Gomycode ; Email = qa.gomycode.<jjmmhhmm>@example.com ; Password = <mot de passe de test – conservé hors document>. | I5: Les valeurs sont acceptées, aucun message d'erreur. | J5: Valeurs acceptées (coche verte sur chaque champ), aucun message d'erreur. | K5: OK | L5: REQ-01 | N5: Exécuté le 21/10/2026 – instance colorful-flock.demo.prestashop.com – Chrome 155 / Windows 11. Saisie faite par le testeur avec ses propres données (Mr / Jaber / EL ABDELLAOUI / email personnel). Mot de passe conservé hors document. | P5: BLOCKED | Q5: Exécution impossible (prérequis/environnement indisponible)
C6: TC-01 | G6: 4 | H6: Cocher les cases obligatoires (Customer data privacy, Terms and conditions). | I6: Les cases sont cochées. | J6: Cases « I agree to the terms and conditions and the privacy policy » et « Customer data privacy » cochées. | K6: OK | L6: REQ-01 | N6: Exécuté le 21/10/2026 – instance colorful-flock.demo.prestashop.com – Chrome 155 / Windows 11. | P6: NOT RUN | Q6: Test non exécuté
C7: TC-01 | G7: 5 | H7: Cliquer sur « Save ». | I7: Le compte est créé, le client est connecté ; « Test Gomycode » et le lien « Sign out » apparaissent dans l'en-tête. | J7: Compte créé, client connecté : l'en-tête affiche « Jaber EL ABDELLAOUI » ; « Sign out » présent dans le menu déroulant sous le nom. | K7: OK | L7: REQ-01 | N7: Exécuté le 21/10/2026 – instance colorful-flock.demo.prestashop.com – Chrome 155 / Windows 11. Bouton réel : « Create account » (pas « Save »). Nom affiché = données saisies (pas « Test Gomycode »). « Sign out » n'est pas directement dans l'en-tête mais dans le menu du compte (cas de test à mettre à jour).
C8: TC-02 | D8: Inscription – champs obligatoires vides | E8: Négatif | F8: Utilisateur non connecté. Formulaire « Create an account » ouvert. | G8: 1 | H8: Laisser First name, Last name, Email et Password vides, puis cliquer sur « Save ». | I8: L'envoi est bloqué ; un message « champ obligatoire » s'affiche sur le premier champ vide ; aucun compte créé. | J8: Envoi bloqué, reste sur /registration ; focus sur First name avec la bulle « Veuillez renseigner ce champ. » ; champs vides encadrés en rouge ; aucun compte créé. | K8: OK | L8: REQ-02 | N8: Exécuté le 21/10/2026 – instance colorful-flock.demo.prestashop.com – Chrome 155 / Windows 11. Validation HTML5 du navigateur (Chrome en français). Cases : « Veuillez cocher cette case si vous souhaitez continuer. » | P8: Saisir uniquement les colonnes J (résultat obtenu), K (statut), M (Bug ID) et N (preuves) lors de l'exécution.
C9: TC-02 | G9: 2 | H9: Remplir tous les champs avec des données valides SANS cocher la case des conditions, puis « Save ». | I9: L'envoi est bloqué ; un message indique que la case est obligatoire ; aucun compte créé. | J9: Envoi bloqué ; la case « I agree to the terms and conditions and the privacy policy » passe en rouge avec la bulle « Veuillez cocher cette case si vous souhaitez continuer. » ; en-tête toujours « Sign in », aucun compte créé. | K9: OK | L9: REQ-02 | N9: Exécuté le 21/10/2026 – instance colorful-flock.demo.prestashop.com – Chrome 155 / Windows 11. Données : Mr / Test / Gomycode / qa.gomycode.21100214@example.com ; Customer data privacy cochée ; mot de passe saisi par le testeur.
C10: TC-03 | D10: Inscription – email au format invalide | E10: Négatif | F10: Utilisateur non connecté. Formulaire « Create an account » ouvert. | G10: 1 | H10: Remplir le formulaire avec des valeurs valides et Email = qa.gomycode.example.com (sans @), puis « Save ». | I10: L'envoi est refusé avec un message de format d'email invalide ; aucun compte créé. | J10: Envoi refusé ; focus sur Email avec le message « Veuillez inclure "@" dans l'adresse e-mail. Il manque un symbole "@" dans "qa.gomycode.example.com". » | K10: OK | L10: REQ-02 | N10: Exécuté le 21/10/2026 – instance colorful-flock.demo.prestashop.com – Chrome 155 / Windows 11. Données : Mr / Test / Gomycode / qa.gomycode.example.com ; Password laissé vide (le message email s'affiche en premier). | P10: Note d'exécution (21/10/2026) : campagne complète (TC-01 à TC-27, suites A à E) exécutée sur la démo PrestaShop via Claude in Chrome (instance colorful-flock.demo.prestashop.com, Chrome 155.0.8059.80, Windows 11). Les saisies de mot de passe ont été faites par le testeur ; aucune commande n'a été passée. Résultat : 2 KO (TC-11 étape 3 → BUG-001 ; TC-17 étape 1 → BUG-002), 1 BLOCKED (TC-14 étape 2 : une seule image produit), toutes les autres étapes OK.
C11: TC-03 | G11: 2 | H11: Remplacer l'email par qa@@example.com, puis « Save ». | I11: L'envoi est refusé avec un message de format d'email invalide. | J11: Envoi refusé avec le message « La partie précédée du symbole "@" ne doit pas contenir le caractère "@". » | K11: OK | L11: REQ-02 | N11: Exécuté le 21/10/2026 – instance colorful-flock.demo.prestashop.com – Chrome 155 / Windows 11. Email : qa@@example.com
C12: TC-04 | D12: Inscription – email déjà utilisé | E12: Négatif | F12: TC-01 exécuté (compte existant). Utilisateur déconnecté. Formulaire « Create an account » ouvert. | G12: 1 | H12: Remplir le formulaire avec l'email du compte créé en TC-01 et des valeurs valides, puis « Save ». | I12: Message indiquant que l'email est déjà utilisé ; aucun second compte créé. | J12: La page se recharge avec le message « The email is already used, please choose another one or sign in » sous le champ Email ; utilisateur non connecté, aucun second compte. | K12: OK | L12: REQ-02 | N12: Exécuté le 21/10/2026 – instance colorful-flock.demo.prestashop.com – Chrome 155 / Windows 11. Données : Mr / Test / Gomycode / email du compte TC-01 ; mot de passe saisi par le testeur.
C13: TC-05 | D13: Connexion avec identifiants valides | E13: Positif | F13: Compte de TC-01 existant. Utilisateur déconnecté. | G13: 1 | H13: Cliquer sur « Sign in ». | I13: La page d'authentification s'affiche. | J13: La page « Sign in » s'affiche. | K13: OK | L13: REQ-03 | N13: Exécuté le 21/10/2026 – instance colorful-flock.demo.prestashop.com – Chrome 155 / Windows 11. URL : /login
C14: TC-05 | G14: 2 | H14: Saisir Email = email du compte TC-01 et Password = <mot de passe de test – conservé hors document>, puis cliquer sur « Sign in ». | I14: Redirection vers « Your account » ; le nom du client s'affiche dans l'en-tête. | J14: Redirection vers « Your account » (fil d'Ariane « Home / Your account ») avec « Welcome Jaber EL ABDELLAOUI » ; nom affiché dans l'en-tête. | K14: OK | L14: REQ-03 | N14: Exécuté le 21/10/2026 – instance colorful-flock.demo.prestashop.com – Chrome 155 / Windows 11. Email du compte TC-01 ; mot de passe saisi par le testeur (hors document).
C15: TC-06 | D15: Connexion avec mot de passe incorrect | E15: Négatif | F15: Compte de TC-01 existant. Utilisateur déconnecté. Page « Sign in » ouverte. | G15: 1 | H15: Saisir l'email du compte TC-01 et le mot de passe « Wrong#Pass1 », puis « Sign in ». | I15: Message « Authentication failed. » ; l'utilisateur reste non connecté sur la page de connexion. | J15: Message « Authentication failed. » dans un bandeau rouge ; reste sur « Sign in », en-tête toujours « Sign in », champ Password vidé. | K15: OK | L15: REQ-03 | N15: Exécuté le 21/10/2026 – instance colorful-flock.demo.prestashop.com – Chrome 155 / Windows 11. Mot de passe : « Wrong#Pass1 »
C16: TC-07 | D16: Connexion avec email inconnu / champs vides | E16: Négatif | F16: Utilisateur déconnecté. Page « Sign in » ouverte. | G16: 1 | H16: Saisir Email = unknown.qa.gomycode@example.com et un mot de passe quelconque, puis « Sign in ». | I16: Message « Authentication failed. » ; aucune connexion. | J16: Après rechargement, message « Authentication failed. » ; aucune connexion (en-tête « Sign in »). | K16: OK | L16: REQ-03 | N16: Exécuté le 21/10/2026 – instance colorful-flock.demo.prestashop.com – Chrome 155 / Windows 11. Email : unknown.qa.gomycode@example.com ; mot de passe quelconque.
C17: TC-07 | G17: 2 | H17: Laisser Email et Password vides, puis « Sign in ». | I17: L'envoi est bloqué par la validation des champs obligatoires. | J17: Envoi bloqué ; focus sur Email avec la bulle « Veuillez renseigner ce champ. » ; Email et Password encadrés en rouge. | K17: OK | L17: REQ-03 | N17: Exécuté le 21/10/2026 – instance colorful-flock.demo.prestashop.com – Chrome 155 / Windows 11. Validation HTML5 du navigateur.
C18: TC-08 | D18: Déconnexion | E18: Positif | F18: Client connecté (TC-05). | G18: 1 | H18: Cliquer sur « Sign out » dans l'en-tête. | I18: Le client est déconnecté ; le lien « Sign in » réapparaît. | J18: Clic sur « Sign out » (menu du compte) : redirection vers « Sign in », le lien « Sign in » réapparaît dans l'en-tête. | K18: OK | L18: REQ-04 | N18: Exécuté le 21/10/2026 – instance colorful-flock.demo.prestashop.com – Chrome 155 / Windows 11. « Sign out » accessible via le menu déroulant sous le nom du client.
C19: TC-08 | G19: 2 | H19: Ouvrir directement l'URL de la page « My account » (/my-account ou index.php?controller=my-account). | I19: Redirection vers la page d'authentification ; aucune donnée du compte n'est affichée. | J19: /en/my-account redirige vers la page « Sign in » (fil d'Ariane « Home / Log in to your account ») ; aucune donnée du compte affichée. | K19: OK | L19: REQ-04 | N19: Exécuté le 21/10/2026 – instance colorful-flock.demo.prestashop.com – Chrome 155 / Windows 11. URL ouverte : https://colorful-flock.demo.prestashop.com/en/my-account
B20: B. Navigation & catalogue | C20: TC-09 | D20: Affichage de la page d'accueil | E20: Positif | F20: Boutique de démo ouverte. | G20: 1 | H20: Ouvrir la page d'accueil de la boutique. | I20: Logo, menu principal (Clothes, Accessories, Art), bannière/carrousel et section « Popular products » s'affichent sans erreur. | J20: Page d'accueil affichée sans erreur : logo « my store », carrousel (« SAMPLE 1 », « Sample 2 », « Sample 3 »), « Custom Text Block », « Featured products », « Special deals ». Menu (icône ☰) : « Clothes », « Accessories », « Art ». | K20: OK | L20: REQ-05 | N20: Exécuté le 21/10/2026 – instance colorful-flock.demo.prestashop.com – Chrome 155 / Windows 11. URL : https://colorful-flock.demo.prestashop.com/. La section s'intitule « Featured products » (pas « Popular products ») et le menu est replié derrière ☰ – libellés du cas de test à mettre à jour.
C21: TC-09 | G21: 2 | H21: Ouvrir une autre page puis cliquer sur le logo. | I21: Retour à la page d'accueil. | J21: Depuis /3-clothes, clic sur le logo → retour à la page d'accueil. | K21: OK | L21: REQ-05 | N21: Exécuté le 21/10/2026 – instance colorful-flock.demo.prestashop.com – Chrome 155 / Windows 11. URL d'arrivée : / (page index).
C22: TC-10 | D22: Navigation par catégories et fil d'Ariane | E22: Positif | F22: Page d'accueil ouverte. | G22: 1 | H22: Cliquer sur la catégorie « Clothes » dans le menu. | I22: La page Clothes s'affiche avec son titre, la liste des produits et le nombre de produits (« There are N products »). | J22: Page « Clothes » : titre, description, sous-catégories Men/Women, « There are 2 products. », 2 produits listés. | K22: OK | L22: REQ-05 | N22: Exécuté le 21/10/2026 – instance colorful-flock.demo.prestashop.com – Chrome 155 / Windows 11. URL : /3-clothes. Le catalogue de démo ne contient que 2 produits dans Clothes.
C23: TC-10 | G23: 2 | H23: Cliquer sur la sous-catégorie « Men ». | I23: Seuls les produits de la sous-catégorie Men s'affichent ; le fil d'Ariane indique Home > Clothes > Men. | J23: Page « Men » : « There is 1 product. » (Hummingbird printed t-shirt) ; fil d'Ariane « Home / Clothes / Men ». | K23: OK | L23: REQ-05 | N23: Exécuté le 21/10/2026 – instance colorful-flock.demo.prestashop.com – Chrome 155 / Windows 11. URL : /4-men
C24: TC-10 | G24: 3 | H24: Cliquer sur « Home » dans le fil d'Ariane. | I24: Retour à la page d'accueil. | J24: Clic sur « Home » dans le fil d'Ariane → retour à la page d'accueil. | K24: OK | L24: REQ-05 | N24: Exécuté le 21/10/2026 – instance colorful-flock.demo.prestashop.com – Chrome 155 / Windows 11. URL : /
C25: TC-11 | D25: Recherche de produits | E25: Positif | F25: Boutique ouverte, champ « Search our catalog » visible. | G25: 1 | H25: Saisir « mug » dans la recherche et valider (Entrée). | I25: La page de résultats liste uniquement des produits contenant « mug » (ex. mugs du catalogue de démo). | J25: « Search results for "mug" » – « There are 5 products. » : Customizable mug, Mug The best is yet to come, Mug The adventure begins, Mug Today is a good day, Pack Mug + Framed poster. | K25: OK | L25: REQ-06 | N25: Exécuté le 21/10/2026 – instance colorful-flock.demo.prestashop.com – Chrome 155 / Windows 11. URL : /search ; recherche « mug » validée par Entrée.
C26: TC-11 | G26: 2 | H26: Saisir « shirt » sans valider. | I26: Des suggestions de produits correspondants apparaissent sous le champ. | J26: Suggestion affichée sous le champ : « Hummingbird printed t-shirt ». | K26: OK | L26: REQ-06 | N26: Exécuté le 21/10/2026 – instance colorful-flock.demo.prestashop.com – Chrome 155 / Windows 11. Saisie « shirt » sans validation.
C27: TC-11 | G27: 3 | H27: Rechercher « zzqxw » (mot inexistant). | I27: Aucun produit ; un message indique qu'aucun résultat n'a été trouvé, sans erreur technique. | J27: « Search results for "zzqxw" » – « There are 7 products. » : Mountain fox cushion, Mountain fox - Vector graphics, Mountain fox notebook, Brown bear - Vector graphics, Hummingbird - Vector graphics, Brown bear notebook, Hummingbird notebook. Aucun message « aucun résultat ». | K27: KO | L27: REQ-06 | M27: BUG-001 | N27: Exécuté le 21/10/2026 – instance colorful-flock.demo.prestashop.com – Chrome 155 / Windows 11. URL : /search?controller=search&s=zzqxw – reproduit 2 fois (saisie + URL directe). Voir rapport BUG-001.
C28: TC-12 | D28: Filtres à facettes | E28: Positif | F28: Page de la catégorie « Clothes » ouverte. | G28: 1 | H28: Cocher un filtre dans le bloc « Filter by » (ex. Size = M). | I28: La liste est filtrée ; le filtre actif est affiché (« Active filters ») et le nombre de produits est mis à jour. | J28: Size = M coché : bandeau « Active filters » avec « Size: M », bouton « Clear all » ; compteur « There are 2 products. » (les 2 produits existent en M). Contrôle complémentaire Color = White → « There is 1 product. ». | K28: OK | L28: REQ-07 | N28: Exécuté le 21/10/2026 – instance colorful-flock.demo.prestashop.com – Chrome 155 / Windows 11. URL : /3-clothes ; filtres Size M puis Size M + Color White.
C29: TC-12 | G29: 2 | H29: Cliquer sur « Clear all ». | I29: Tous les filtres sont retirés ; la liste complète réapparaît. | J29: Après « Clear all » : plus de bandeau « Active filters », aucune case cochée, « There are 2 products. » (liste complète). | K29: OK | L29: REQ-07 | N29: Exécuté le 21/10/2026 – instance colorful-flock.demo.prestashop.com – Chrome 155 / Windows 11. URL : /3-clothes
C30: TC-13 | D30: Tri des produits | E30: Positif | F30: Page d'une catégorie contenant plusieurs produits ouverte (ex. Accessories). | G30: 1 | H30: Choisir « Sort by: Price, low to high ». | I30: Les produits s'affichent par prix croissant. | J30: « Price, low to high » : prix croissants (14,28 € ×3 ; 15,48 € ×3 ; 16,68 € ; 22,68 € ×3 ; 42,00 €). | K30: OK | L30: REQ-07 | N30: Exécuté le 21/10/2026 – instance colorful-flock.demo.prestashop.com – Chrome 155 / Windows 11. URL : /6-accessories (11 produits).
C31: TC-13 | G31: 2 | H31: Choisir « Sort by: Name, A to Z ». | I31: Les produits s'affichent par ordre alphabétique croissant. | J31: « Name, A to Z » : ordre alphabétique de « Brown bear cushion » à « Pack Mug + Framed poster » (vérifié par comparaison automatique). | K31: OK | L31: REQ-07 | N31: Exécuté le 21/10/2026 – instance colorful-flock.demo.prestashop.com – Chrome 155 / Windows 11. URL : /6-accessories
C32: TC-14 | D32: Fiche produit | E32: Positif | F32: Page de la catégorie « Clothes » ouverte. | G32: 1 | H32: Cliquer sur le produit « Hummingbird printed t-shirt ». | I32: La fiche affiche nom, prix, images, description, choix de taille/couleur, quantité et bouton « Add to cart ». | J32: Fiche affichée : nom « Hummingbird printed t-shirt », prix « €22.94 » (barré « €28.68 », « Save 20% », « Tax included »), image, description, Size (S/M/L/XL), Color (White/Black), quantité 1, bouton « Add to cart ». | K32: OK | L32: REQ-08 | N32: Exécuté le 21/10/2026 – instance colorful-flock.demo.prestashop.com – Chrome 155 / Windows 11. URL : /1-1-hummingbird-printed-t-shirt.html ; fil d'Ariane Home / Clothes / Men / Hummingbird printed t-shirt.
C33: TC-14 | G33: 2 | H33: Changer la taille (ex. S → L) et cliquer sur une miniature d'image. | I33: La sélection de taille est mise à jour ; l'image principale change. | J33: Taille S → L : « Size: L » affiché, URL mise à jour. Une seule miniature disponible : le clic ne change pas l'image principale. | K33: BLOCKED | L33: REQ-08 | N33: Exécuté le 21/10/2026 – instance colorful-flock.demo.prestashop.com – Chrome 155 / Windows 11. URL : /1-5-hummingbird-printed-t-shirt.html. Changement d'image non vérifiable : la variante White n'a qu'une image (prévoir un produit avec 2+ images).
C34: TC-15 | D34: Pagination des listes | E34: Positif | F34: Une liste comportant plus d'une page de produits est ouverte (ex. résultats d'une recherche large ou catégorie « Home »). | G34: 1 | H34: Cliquer sur la page « 2 » ou sur « Next » en bas de liste. | I34: Une nouvelle série de produits s'affiche ; l'indicateur de page est mis à jour. | J34: Clic sur « › » (page suivante) : « Showing 13-19 of 19 item(s) », 7 nouveaux produits (dont « Brown bear - Vector graphics »), page active « 2 ». | K34: OK | L34: REQ-08 | N34: Exécuté le 21/10/2026 – instance colorful-flock.demo.prestashop.com – Chrome 155 / Windows 11. URL : /2-home (19 produits, 12 par page). Les boutons sont des flèches ‹ › (pas de texte « Next/Previous »).
C35: TC-15 | G35: 2 | H35: Cliquer sur « Previous ». | I35: Retour à la première page de résultats. | J35: Clic sur « ‹ » (page précédente) : « Showing 1-12 of 19 item(s) », 12 premiers produits, page active « 1 ». | K35: OK | L35: REQ-08 | N35: Exécuté le 21/10/2026 – instance colorful-flock.demo.prestashop.com – Chrome 155 / Windows 11. URL : /2-home
B36: C. Panier | C36: TC-16 | D36: Ajout d'un produit au panier | E36: Positif | F36: Panier vide. Fiche « Hummingbird printed t-shirt » ouverte. | G36: 1 | H36: Laisser la quantité à 1 et cliquer sur « Add to cart ». | I36: Fenêtre « Product successfully added to your shopping cart » avec nom, quantité, prix et total ; le compteur du panier passe à 1. | J36: Fenêtre « Added to your cart » : « Hummingbird printed t-shirt has been added to your cart. », €22.94, Size: S, Color: White, Quantity: 1, « There is 1 item in your cart. », Subtotal €22.94, Shipping Free, Total (tax incl.) €22.94 ; compteur « Cart 1 ». | K36: OK | L36: REQ-09 | N36: Exécuté le 21/10/2026 – instance colorful-flock.demo.prestashop.com – Chrome 155 / Windows 11. URL : /1-1-hummingbird-printed-t-shirt.html. Titre réel « Added to your cart » (pas « Product successfully added to your shopping cart »).
C37: TC-16 | G37: 2 | H37: Cliquer sur « Proceed to checkout » dans la fenêtre. | I37: La page du panier (« Shopping Cart ») affiche le produit ajouté. | J37: Page « Shopping Cart » : Hummingbird printed t-shirt (S, White) €22.94, quantité 1. | K37: OK | L37: REQ-09 | N37: Exécuté le 21/10/2026 – instance colorful-flock.demo.prestashop.com – Chrome 155 / Windows 11. URL : /cart
C38: TC-17 | D38: Modification des quantités | E38: Positif | F38: Panier contenant 1 article (TC-16). Page du panier ouverte. | G38: 1 | H38: Cliquer 2 fois sur « + » de la ligne produit. | I38: Quantité = 3 ; total de ligne = prix unitaire × 3 ; total du panier mis à jour. | J38: Quantité = 3, compteur « Cart 3 » ; total de ligne et total affichés €68.83 alors que 3 × €22.94 = €68.82. | K38: KO | L38: REQ-10 | M38: BUG-002 | N38: Exécuté le 21/10/2026 – instance colorful-flock.demo.prestashop.com – Chrome 155 / Windows 11. Écart d'arrondi de 0,01 €. Voir rapport BUG-002.
C39: TC-17 | G39: 2 | H39: Saisir 2 dans le champ quantité et valider. | I39: Quantité = 2 ; totaux recalculés. | J39: Quantité 2 saisie + Entrée : total de ligne et total « €45.89 », « 2 items », « Cart 2 ». | K39: OK | L39: REQ-10 | N39: Exécuté le 21/10/2026 – instance colorful-flock.demo.prestashop.com – Chrome 155 / Windows 11. Totaux recalculés ; même écart d'arrondi (2 × €22.94 = €45.88) – rattaché à BUG-002.
C40: TC-18 | D40: Calcul du total du panier | E40: Positif | F40: Panier contenant au moins 2 produits différents. | G40: 1 | H40: Relever le total de chaque ligne et le sous-total affiché. | I40: Sous-total = somme des totaux de ligne. | J40: Lignes : t-shirt ×2 = €45.89 ; Mug Today is a good day ×1 = €14.28 ; sous-total « 3 items €60.17 » (45.89 + 14.28 = 60.17). | K40: OK | L40: REQ-10 | N40: Exécuté le 21/10/2026 – instance colorful-flock.demo.prestashop.com – Chrome 155 / Windows 11. URL : /cart?action=show
...

Sheet Exigences (REQ → TC)
A1: ID exigence | B1: Description de l'exigence | C1: Source | D1: Priorité | E1: Cas de test couvrants | F1: Nb cas de test | G1: Étapes OK | H1: Étapes KO | I1: Étapes BLOCKED | J1: Étapes NOT RUN | K1: Statut exigence
A2: REQ-01 | B2: Un visiteur peut créer un compte client en renseignant les champs obligatoires. | C2: Brief §4.A | D2: Haute | E2: TC-01 | F2: =SUMPRODUCT(('Matrice de traçabilité'!$L$3:$L$61=A2)*('Matrice de traçabilité'!$G$3:$G$61=1)) -> 1 | G2: =COUNTIFS('Matrice de traçabilité'!$L$3:$L$61,A2,'Matrice de traçabilité'!$K$3:$K$61,"OK") -> 5 | H2: =COUNTIFS('Matrice de traçabilité'!$L$3:$L$61,A2,'Matrice de traçabilité'!$K$3:$K$61,"KO") -> 0 | I2: =COUNTIFS('Matrice de traçabilité'!$L$3:$L$61,A2,'Matrice de traçabilité'!$K$3:$K$61,"BLOCKED") -> 0 | J2: =COUNTIFS('Matrice de traçabilité'!$L$3:$L$61,A2,'Matrice de traçabilité'!$K$3:$K$61,"NOT RUN") -> 0 | K2: =IF(F2=0,"NON COUVERTE",IF(H2>0,"KO",IF(I2>0,"BLOCKED",IF(J2>0,"NOT RUN","OK")))) -> OK
A3: REQ-02 | B3: Le formulaire d'inscription refuse les champs obligatoires vides, un email invalide ou déjà utilisé, avec un message explicite. | C3: Brief §4.A | D3: Haute | E3: TC-02, TC-03, TC-04 | F3: =SUMPRODUCT(('Matrice de traçabilité'!$L$3:$L$61=A3)*('Matrice de traçabilité'!$G$3:$G$61=1)) -> 3 | G3: =COUNTIFS('Matrice de traçabilité'!$L$3:$L$61,A3,'Matrice de traçabilité'!$K$3:$K$61,"OK") -> 5 | H3: =COUNTIFS('Matrice de traçabilité'!$L$3:$L$61,A3,'Matrice de traçabilité'!$K$3:$K$61,"KO") -> 0 | I3: =COUNTIFS('Matrice de traçabilité'!$L$3:$L$61,A3,'Matrice de traçabilité'!$K$3:$K$61,"BLOCKED") -> 0 | J3: =COUNTIFS('Matrice de traçabilité'!$L$3:$L$61,A3,'Matrice de traçabilité'!$K$3:$K$61,"NOT RUN") -> 0 | K3: =IF(F3=0,"NON COUVERTE",IF(H3>0,"KO",IF(I3>0,"BLOCKED",IF(J3>0,"NOT RUN","OK")))) -> OK
A4: REQ-03 | B4: Un client se connecte avec des identifiants valides ; toute connexion avec identifiants invalides est refusée. | C4: Brief §4.A | D4: Haute | E4: TC-05, TC-06, TC-07 | F4: =SUMPRODUCT(('Matrice de traçabilité'!$L$3:$L$61=A4)*('Matrice de traçabilité'!$G$3:$G$61=1)) -> 3 | G4: =COUNTIFS('Matrice de traçabilité'!$L$3:$L$61,A4,'Matrice de traçabilité'!$K$3:$K$61,"OK") -> 5 | H4: =COUNTIFS('Matrice de traçabilité'!$L$3:$L$61,A4,'Matrice de traçabilité'!$K$3:$K$61,"KO") -> 0 | I4: =COUNTIFS('Matrice de traçabilité'!$L$3:$L$61,A4,'Matrice de traçabilité'!$K$3:$K$61,"BLOCKED") -> 0 | J4: =COUNTIFS('Matrice de traçabilité'!$L$3:$L$61,A4,'Matrice de traçabilité'!$K$3:$K$61,"NOT RUN") -> 0 | K4: =IF(F4=0,"NON COUVERTE",IF(H4>0,"KO",IF(I4>0,"BLOCKED",IF(J4>0,"NOT RUN","OK")))) -> OK
A5: REQ-04 | B5: Un client connecté peut se déconnecter ; les pages privées ne sont plus accessibles. | C5: Brief §4.A | D5: Haute | E5: TC-08 | F5: =SUMPRODUCT(('Matrice de traçabilité'!$L$3:$L$61=A5)*('Matrice de traçabilité'!$G$3:$G$61=1)) -> 1 | G5: =COUNTIFS('Matrice de traçabilité'!$L$3:$L$61,A5,'Matrice de traçabilité'!$K$3:$K$61,"OK") -> 2 | H5: =COUNTIFS('Matrice de traçabilité'!$L$3:$L$61,A5,'Matrice de traçabilité'!$K$3:$K$61,"KO") -> 0 | I5: =COUNTIFS('Matrice de traçabilité'!$L$3:$L$61,A5,'Matrice de traçabilité'!$K$3:$K$61,"BLOCKED") -> 0 | J5: =COUNTIFS('Matrice de traçabilité'!$L$3:$L$61,A5,'Matrice de traçabilité'!$K$3:$K$61,"NOT RUN") -> 0 | K5: =IF(F5=0,"NON COUVERTE",IF(H5>0,"KO",IF(I5>0,"BLOCKED",IF(J5>0,"NOT RUN","OK")))) -> OK
A6: REQ-05 | B6: La page d'accueil et le menu des catégories permettent de naviguer dans le catalogue. | C6: Brief §4.B | D6: Moyenne | E6: TC-09, TC-10 | F6: =SUMPRODUCT(('Matrice de traçabilité'!$L$3:$L$61=A6)*('Matrice de traçabilité'!$G$3:$G$61=1)) -> 2 | G6: =COUNTIFS('Matrice de traçabilité'!$L$3:$L$61,A6,'Matrice de traçabilité'!$K$3:$K$61,"OK") -> 5 | H6: =COUNTIFS('Matrice de traçabilité'!$L$3:$L$61,A6,'Matrice de traçabilité'!$K$3:$K$61,"KO") -> 0 | I6: =COUNTIFS('Matrice de traçabilité'!$L$3:$L$61,A6,'Matrice de traçabilité'!$K$3:$K$61,"BLOCKED") -> 0 | J6: =COUNTIFS('Matrice de traçabilité'!$L$3:$L$61,A6,'Matrice de traçabilité'!$K$3:$K$61,"NOT RUN") -> 0 | K6: =IF(F6=0,"NON COUVERTE",IF(H6>0,"KO",IF(I6>0,"BLOCKED",IF(J6>0,"NOT RUN","OK")))) -> OK
A7: REQ-06 | B7: La recherche renvoie les produits correspondant au mot-clé, ou un message si aucun résultat. | C7: Brief §4.B | D7: Haute | E7: TC-11 | F7: =SUMPRODUCT(('Matrice de traçabilité'!$L$3:$L$61=A7)*('Matrice de traçabilité'!$G$3:$G$61=1)) -> 1 | G7: =COUNTIFS('Matrice de traçabilité'!$L$3:$L$61,A7,'Matrice de traçabilité'!$K$3:$K$61,"OK") -> 2 | H7: =COUNTIFS('Matrice de traçabilité'!$L$3:$L$61,A7,'Matrice de traçabilité'!$K$3:$K$61,"KO") -> 1 | I7: =COUNTIFS('Matrice de traçabilité'!$L$3:$L$61,A7,'Matrice de traçabilité'!$K$3:$K$61,"BLOCKED") -> 0 | J7: =COUNTIFS('Matrice de traçabilité'!$L$3:$L$61,A7,'Matrice de traçabilité'!$K$3:$K$61,"NOT RUN") -> 0 | K7: =IF(F7=0,"NON COUVERTE",IF(H7>0,"KO",IF(I7>0,"BLOCKED",IF(J7>0,"NOT RUN","OK")))) -> KO
A8: REQ-07 | B8: Les filtres (facettes) et le tri réorganisent correctement la liste des produits. | C8: Brief §4.B | D8: Moyenne | E8: TC-12, TC-13 | F8: =SUMPRODUCT(('Matrice de traçabilité'!$L$3:$L$61=A8)*('Matrice de traçabilité'!$G$3:$G$61=1)) -> 2 | G8: =COUNTIFS('Matrice de traçabilité'!$L$3:$L$61,A8,'Matrice de traçabilité'!$K$3:$K$61,"OK") -> 4 | H8: =COUNTIFS('Matrice de traçabilité'!$L$3:$L$61,A8,'Matrice de traçabilité'!$K$3:$K$61,"KO") -> 0 | I8: =COUNTIFS('Matrice de traçabilité'!$L$3:$L$61,A8,'Matrice de traçabilité'!$K$3:$K$61,"BLOCKED") -> 0 | J8: =COUNTIFS('Matrice de traçabilité'!$L$3:$L$61,A8,'Matrice de traçabilité'!$K$3:$K$61,"NOT RUN") -> 0 | K8: =IF(F8=0,"NON COUVERTE",IF(H8>0,"KO",IF(I8>0,"BLOCKED",IF(J8>0,"NOT RUN","OK")))) -> OK
A9: REQ-08 | B9: La fiche produit affiche les informations du produit ; la pagination permet de parcourir les listes. | C9: Brief §4.B | D9: Moyenne | E9: TC-14, TC-15 | F9: =SUMPRODUCT(('Matrice de traçabilité'!$L$3:$L$61=A9)*('Matrice de traçabilité'!$G$3:$G$61=1)) -> 2 | G9: =COUNTIFS('Matrice de traçabilité'!$L$3:$L$61,A9,'Matrice de traçabilité'!$K$3:$K$61,"OK") -> 3 | H9: =COUNTIFS('Matrice de traçabilité'!$L$3:$L$61,A9,'Matrice de traçabilité'!$K$3:$K$61,"KO") -> 0 | I9: =COUNTIFS('Matrice de traçabilité'!$L$3:$L$61,A9,'Matrice de traçabilité'!$K$3:$K$61,"BLOCKED") -> 1 | J9: =COUNTIFS('Matrice de traçabilité'!$L$3:$L$61,A9,'Matrice de traçabilité'!$K$3:$K$61,"NOT RUN") -> 0 | K9: =IF(F9=0,"NON COUVERTE",IF(H9>0,"KO",IF(I9>0,"BLOCKED",IF(J9>0,"NOT RUN","OK")))) -> BLOCKED
A10: REQ-09 | B10: Un produit peut être ajouté au panier depuis sa fiche. | C10: Brief §4.C | D10: Haute | E10: TC-16 | F10: =SUMPRODUCT(('Matrice de traçabilité'!$L$3:$L$61=A10)*('Matrice de traçabilité'!$G$3:$G$61=1)) -> 1 | G10: =COUNTIFS('Matrice de traçabilité'!$L$3:$L$61,A10,'Matrice de traçabilité'!$K$3:$K$61,"OK") -> 2 | H10: =COUNTIFS('Matrice de traçabilité'!$L$3:$L$61,A10,'Matrice de traçabilité'!$K$3:$K$61,"KO") -> 0 | I10: =COUNTIFS('Matrice de traçabilité'!$L$3:$L$61,A10,'Matrice de traçabilité'!$K$3:$K$61,"BLOCKED") -> 0 | J10: =COUNTIFS('Matrice de traçabilité'!$L$3:$L$61,A10,'Matrice de traçabilité'!$K$3:$K$61,"NOT RUN") -> 0 | K10: =IF(F10=0,"NON COUVERTE",IF(H10>0,"KO",IF(I10>0,"BLOCKED",IF(J10>0,"NOT RUN","OK")))) -> OK
A11: REQ-10 | B11: Le panier permet de modifier les quantités, supprimer un produit, calcule le total et gère le panier vide. | C11: Brief §4.C | D11: Haute | E11: TC-17, TC-18, TC-19 | F11: =SUMPRODUCT(('Matrice de traçabilité'!$L$3:$L$61=A11)*('Matrice de traçabilité'!$G$3:$G$61=1)) -> 3 | G11: =COUNTIFS('Matrice de traçabilité'!$L$3:$L$61,A11,'Matrice de traçabilité'!$K$3:$K$61,"OK") -> 5 | H11: =COUNTIFS('Matrice de traçabilité'!$L$3:$L$61,A11,'Matrice de traçabilité'!$K$3:$K$61,"KO") -> 1 | I11: =COUNTIFS('Matrice de traçabilité'!$L$3:$L$61,A11,'Matrice de traçabilité'!$K$3:$K$61,"BLOCKED") -> 0 | J11: =COUNTIFS('Matrice de traçabilité'!$L$3:$L$61,A11,'Matrice de traçabilité'!$K$3:$K$61,"NOT RUN") -> 0 | K11: =IF(F11=0,"NON COUVERTE",IF(H11>0,"KO",IF(I11>0,"BLOCKED",IF(J11>0,"NOT RUN","OK")))) -> KO
A12: REQ-11 | B12: Le tunnel de commande permet de saisir/valider l'adresse, choisir un transporteur et vérifier le récapitulatif (sans valider de commande). | C12: Brief §4.D | D12: Haute | E12: TC-20, TC-21, TC-22, TC-23 | F12: =SUMPRODUCT(('Matrice de traçabilité'!$L$3:$L$61=A12)*('Matrice de traçabilité'!$G$3:$G$61=1)) -> 4 | G12: =COUNTIFS('Matrice de traçabilité'!$L$3:$L$61,A12,'Matrice de traçabilité'!$K$3:$K$61,"OK") -> 9 | H12: =COUNTIFS('Matrice de traçabilité'!$L$3:$L$61,A12,'Matrice de traçabilité'!$K$3:$K$61,"KO") -> 0 | I12: =COUNTIFS('Matrice de traçabilité'!$L$3:$L$61,A12,'Matrice de traçabilité'!$K$3:$K$61,"BLOCKED") -> 0 | J12: =COUNTIFS('Matrice de traçabilité'!$L$3:$L$61,A12,'Matrice de traçabilité'!$K$3:$K$61,"NOT RUN") -> 0 | K12: =IF(F12=0,"NON COUVERTE",IF(H12>0,"KO",IF(I12>0,"BLOCKED",IF(J12>0,"NOT RUN","OK")))) -> OK
A13: REQ-12 | B13: L'espace client permet de consulter/modifier ses informations, gérer ses adresses et voir l'historique des commandes. | C13: Brief §4.E | D13: Moyenne | E13: TC-24, TC-25, TC-26, TC-27 | F13: =SUMPRODUCT(('Matrice de traçabilité'!$L$3:$L$61=A13)*('Matrice de traçabilité'!$G$3:$G$61=1)) -> 4 | G13: =COUNTIFS('Matrice de traçabilité'!$L$3:$L$61,A13,'Matrice de traçabilité'!$K$3:$K$61,"OK") -> 9 | H13: =COUNTIFS('Matrice de traçabilité'!$L$3:$L$61,A13,'Matrice de traçabilité'!$K$3:$K$61,"KO") -> 0 | I13: =COUNTIFS('Matrice de traçabilité'!$L$3:$L$61,A13,'Matrice de traçabilité'!$K$3:$K$61,"BLOCKED") -> 0 | J13: =COUNTIFS('Matrice de traçabilité'!$L$3:$L$61,A13,'Matrice de traçabilité'!$K$3:$K$61,"NOT RUN") -> 0 | K13: =IF(F13=0,"NON COUVERTE",IF(H13>0,"KO",IF(I13>0,"BLOCKED",IF(J13>0,"NOT RUN","OK")))) -> OK

Sheet Synthèse
A1: ID test | B1: Titre du test | C1: Type | D1: Suite | E1: ID exigence | F1: Nb étapes | G1: Statut du test | H1: Bug ID | K1: Indicateurs (calculés automatiquement)
A2: TC-01 | B2: Création d'un compte client valide | C2: Positif | D2: A. Inscription & authentification | E2: REQ-01 | F2: =COUNTIF('Matrice de traçabilité'!$C$3:$C$61,A2) -> 5 | G2: =IF(COUNTIFS('Matrice de traçabilité'!$C$3:$C$61,A2,'Matrice de traçabilité'!$K$3:$K$61,"KO")>0,"KO",IF(COUNTIFS('Matrice de traçabilité'!$C$3:$C$61,A2,'Matrice de traçabilité'!$K$3:$K$61,"BLOCKED")>0,"BLOCKED",IF(COUNTIFS('Matrice de traçabilité'!$C$3:$C$61,A2,'Matrice de traçabilité'!$K$3:$K$61,"NOT RUN")>0,"NOT RUN","OK"))) -> OK | H2: =IF(COUNTIFS('Matrice de traçabilité'!$C$3:$C$61,A2,'Matrice de traçabilité'!$M$3:$M$61,"<>")=0,"",INDEX('Matrice de traçabilité'!$M$3:$M$61,MATCH(1,INDEX(('Matrice de traçabilité'!$C$3:$C$61=A2)*('Matrice de traçabilité'!$M$3:$M$61<>""),0),0))) | K2: Nombre total de cas de test | L2: =COUNTA($A$2:$A$28) -> 27
A3: TC-02 | B3: Inscription – champs obligatoires vides | C3: Négatif | D3: A. Inscription & authentification | E3: REQ-02 | F3: =COUNTIF('Matrice de traçabilité'!$C$3:$C$61,A3) -> 2 | G3: =IF(COUNTIFS('Matrice de traçabilité'!$C$3:$C$61,A3,'Matrice de traçabilité'!$K$3:$K$61,"KO")>0,"KO",IF(COUNTIFS('Matrice de traçabilité'!$C$3:$C$61,A3,'Matrice de traçabilité'!$K$3:$K$61,"BLOCKED")>0,"BLOCKED",IF(COUNTIFS('Matrice de traçabilité'!$C$3:$C$61,A3,'Matrice de traçabilité'!$K$3:$K$61,"NOT RUN")>0,"NOT RUN","OK"))) -> OK | H3: =IF(COUNTIFS('Matrice de traçabilité'!$C$3:$C$61,A3,'Matrice de traçabilité'!$M$3:$M$61,"<>")=0,"",INDEX('Matrice de traçabilité'!$M$3:$M$61,MATCH(1,INDEX(('Matrice de traçabilité'!$C$3:$C$61=A3)*('Matrice de traçabilité'!$M$3:$M$61<>""),0),0))) | K3: Tests exécutés (OK + KO) | L3: =L4+L5 -> 26
A4: TC-03 | B4: Inscription – email au format invalide | C4: Négatif | D4: A. Inscription & authentification | E4: REQ-02 | F4: =COUNTIF('Matrice de traçabilité'!$C$3:$C$61,A4) -> 2 | G4: =IF(COUNTIFS('Matrice de traçabilité'!$C$3:$C$61,A4,'Matrice de traçabilité'!$K$3:$K$61,"KO")>0,"KO",IF(COUNTIFS('Matrice de traçabilité'!$C$3:$C$61,A4,'Matrice de traçabilité'!$K$3:$K$61,"BLOCKED")>0,"BLOCKED",IF(COUNTIFS('Matrice de traçabilité'!$C$3:$C$61,A4,'Matrice de traçabilité'!$K$3:$K$61,"NOT RUN")>0,"NOT RUN","OK"))) -> OK | H4: =IF(COUNTIFS('Matrice de traçabilité'!$C$3:$C$61,A4,'Matrice de traçabilité'!$M$3:$M$61,"<>")=0,"",INDEX('Matrice de traçabilité'!$M$3:$M$61,MATCH(1,INDEX(('Matrice de traçabilité'!$C$3:$C$61=A4)*('Matrice de traçabilité'!$M$3:$M$61<>""),0),0))) | K4: PASS (OK) | L4: =COUNTIF($G$2:$G$28,"OK") -> 24
A5: TC-04 | B5: Inscription – email déjà utilisé | C5: Négatif | D5: A. Inscription & authentification | E5: REQ-02 | F5: =COUNTIF('Matrice de traçabilité'!$C$3:$C$61,A5) -> 1 | G5: =IF(COUNTIFS('Matrice de traçabilité'!$C$3:$C$61,A5,'Matrice de traçabilité'!$K$3:$K$61,"KO")>0,"KO",IF(COUNTIFS('Matrice de traçabilité'!$C$3:$C$61,A5,'Matrice de traçabilité'!$K$3:$K$61,"BLOCKED")>0,"BLOCKED",IF(COUNTIFS('Matrice de traçabilité'!$C$3:$C$61,A5,'Matrice de traçabilité'!$K$3:$K$61,"NOT RUN")>0,"NOT RUN","OK"))) -> OK | H5: =IF(COUNTIFS('Matrice de traçabilité'!$C$3:$C$61,A5,'Matrice de traçabilité'!$M$3:$M$61,"<>")=0,"",INDEX('Matrice de traçabilité'!$M$3:$M$61,MATCH(1,INDEX(('Matrice de traçabilité'!$C$3:$C$61=A5)*('Matrice de traçabilité'!$M$3:$M$61<>""),0),0))) | K5: FAIL (KO) | L5: =COUNTIF($G$2:$G$28,"KO") -> 2
A6: TC-05 | B6: Connexion avec identifiants valides | C6: Positif | D6: A. Inscription & authentification | E6: REQ-03 | F6: =COUNTIF('Matrice de traçabilité'!$C$3:$C$61,A6) -> 2 | G6: =IF(COUNTIFS('Matrice de traçabilité'!$C$3:$C$61,A6,'Matrice de traçabilité'!$K$3:$K$61,"KO")>0,"KO",IF(COUNTIFS('Matrice de traçabilité'!$C$3:$C$61,A6,'Matrice de traçabilité'!$K$3:$K$61,"BLOCKED")>0,"BLOCKED",IF(COUNTIFS('Matrice de traçabilité'!$C$3:$C$61,A6,'Matrice de traçabilité'!$K$3:$K$61,"NOT RUN")>0,"NOT RUN","OK"))) -> OK | H6: =IF(COUNTIFS('Matrice de traçabilité'!$C$3:$C$61,A6,'Matrice de traçabilité'!$M$3:$M$61,"<>")=0,"",INDEX('Matrice de traçabilité'!$M$3:$M$61,MATCH(1,INDEX(('Matrice de traçabilité'!$C$3:$C$61=A6)*('Matrice de traçabilité'!$M$3:$M$61<>""),0),0))) | K6: BLOCKED | L6: =COUNTIF($G$2:$G$28,"BLOCKED") -> 1
A7: TC-06 | B7: Connexion avec mot de passe incorrect | C7: Négatif | D7: A. Inscription & authentification | E7: REQ-03 | F7: =COUNTIF('Matrice de traçabilité'!$C$3:$C$61,A7) -> 1 | G7: =IF(COUNTIFS('Matrice de traçabilité'!$C$3:$C$61,A7,'Matrice de traçabilité'!$K$3:$K$61,"KO")>0,"KO",IF(COUNTIFS('Matrice de traçabilité'!$C$3:$C$61,A7,'Matrice de traçabilité'!$K$3:$K$61,"BLOCKED")>0,"BLOCKED",IF(COUNTIFS('Matrice de traçabilité'!$C$3:$C$61,A7,'Matrice de traçabilité'!$K$3:$K$61,"NOT RUN")>0,"NOT RUN","OK"))) -> OK | H7: =IF(COUNTIFS('Matrice de traçabilité'!$C$3:$C$61,A7,'Matrice de traçabilité'!$M$3:$M$61,"<>")=0,"",INDEX('Matrice de traçabilité'!$M$3:$M$61,MATCH(1,INDEX(('Matrice de traçabilité'!$C$3:$C$61=A7)*('Matrice de traçabilité'!$M$3:$M$61<>""),0),0))) | K7: NOT RUN | L7: =COUNTIF($G$2:$G$28,"NOT RUN") -> 0
A8: TC-07 | B8: Connexion avec email inconnu / champs vides | C8: Négatif | D8: A. Inscription & authentification | E8: REQ-03 | F8: =COUNTIF('Matrice de traçabilité'!$C$3:$C$61,A8) -> 2 | G8: =IF(COUNTIFS('Matrice de traçabilité'!$C$3:$C$61,A8,'Matrice de traçabilité'!$K$3:$K$61,"KO")>0,"KO",IF(COUNTIFS('Matrice de traçabilité'!$C$3:$C$61,A8,'Matrice de traçabilité'!$K$3:$K$61,"BLOCKED")>0,"BLOCKED",IF(COUNTIFS('Matrice de traçabilité'!$C$3:$C$61,A8,'Matrice de traçabilité'!$K$3:$K$61,"NOT RUN")>0,"NOT RUN","OK"))) -> OK | H8: =IF(COUNTIFS('Matrice de traçabilité'!$C$3:$C$61,A8,'Matrice de traçabilité'!$M$3:$M$61,"<>")=0,"",INDEX('Matrice de traçabilité'!$M$3:$M$61,MATCH(1,INDEX(('Matrice de traçabilité'!$C$3:$C$61=A8)*('Matrice de traçabilité'!$M$3:$M$61<>""),0),0))) | K8: Bugs confirmés (Bug ID distincts, lot 1 col. M) | L8: =SUMPRODUCT(('Matrice de traçabilité'!$M$3:$M$61<>"")/COUNTIF('Matrice de traçabilité'!$M$3:$M$61,'Matrice de traçabilité'!$M$3:$M$61&"")) -> 2
A9: TC-08 | B9: Déconnexion | C9: Positif | D9: A. Inscription & authentification | E9: REQ-04 | F9: =COUNTIF('Matrice de traçabilité'!$C$3:$C$61,A9) -> 2 | G9: =IF(COUNTIFS('Matrice de traçabilité'!$C$3:$C$61,A9,'Matrice de traçabilité'!$K$3:$K$61,"KO")>0,"KO",IF(COUNTIFS('Matrice de traçabilité'!$C$3:$C$61,A9,'Matrice de traçabilité'!$K$3:$K$61,"BLOCKED")>0,"BLOCKED",IF(COUNTIFS('Matrice de traçabilité'!$C$3:$C$61,A9,'Matrice de traçabilité'!$K$3:$K$61,"NOT RUN")>0,"NOT RUN","OK"))) -> OK | H9: =IF(COUNTIFS('Matrice de traçabilité'!$C$3:$C$61,A9,'Matrice de traçabilité'!$M$3:$M$61,"<>")=0,"",INDEX('Matrice de traçabilité'!$M$3:$M$61,MATCH(1,INDEX(('Matrice de traçabilité'!$C$3:$C$61=A9)*('Matrice de traçabilité'!$M$3:$M$61<>""),0),0))) | K9: Taux de réussite (OK / exécutés) | L9: =IF(L3=0,"N/A – aucun test exécuté",L4/L3) -> 0.92307692
A10: TC-09 | B10: Affichage de la page d'accueil | C10: Positif | D10: B. Navigation & catalogue | E10: REQ-05 | F10: =COUNTIF('Matrice de traçabilité'!$C$3:$C$61,A10) -> 2 | G10: =IF(COUNTIFS('Matrice de traçabilité'!$C$3:$C$61,A10,'Matrice de traçabilité'!$K$3:$K$61,"KO")>0,"KO",IF(COUNTIFS('Matrice de traçabilité'!$C$3:$C$61,A10,'Matrice de traçabilité'!$K$3:$K$61,"BLOCKED")>0,"BLOCKED",IF(COUNTIFS('Matrice de traçabilité'!$C$3:$C$61,A10,'Matrice de traçabilité'!$K$3:$K$61,"NOT RUN")>0,"NOT RUN","OK"))) -> OK | H10: =IF(COUNTIFS('Matrice de traçabilité'!$C$3:$C$61,A10,'Matrice de traçabilité'!$M$3:$M$61,"<>")=0,"",INDEX('Matrice de traçabilité'!$M$3:$M$61,MATCH(1,INDEX(('Matrice de traçabilité'!$C$3:$C$61=A10)*('Matrice de traçabilité'!$M$3:$M$61<>""),0),0))) | K10: Exigences couvertes / total | L10: =COUNTIF('Exigences (REQ → TC)'!F2:F13,">0")&" / "&COUNTA('Exigences (REQ → TC)'!A2:A13) -> 12 / 12
A11: TC-10 | B11: Navigation par catégories et fil d'Ariane | C11: Positif | D11: B. Navigation & catalogue | E11: REQ-05 | F11: =COUNTIF('Matrice de traçabilité'!$C$3:$C$61,A11) -> 3 | G11: =IF(COUNTIFS('Matrice de traçabilité'!$C$3:$C$61,A11,'Matrice de traçabilité'!$K$3:$K$61,"KO")>0,"KO",IF(COUNTIFS('Matrice de traçabilité'!$C$3:$C$61,A11,'Matrice de traçabilité'!$K$3:$K$61,"BLOCKED")>0,"BLOCKED",IF(COUNTIFS('Matrice de traçabilité'!$C$3:$C$61,A11,'Matrice de traçabilité'!$K$3:$K$61,"NOT RUN")>0,"NOT RUN","OK"))) -> OK | H11: =IF(COUNTIFS('Matrice de traçabilité'!$C$3:$C$61,A11,'Matrice de traçabilité'!$M$3:$M$61,"<>")=0,"",INDEX('Matrice de traçabilité'!$M$3:$M$61,MATCH(1,INDEX(('Matrice de traçabilité'!$C$3:$C$61=A11)*('Matrice de traçabilité'!$M$3:$M$61<>""),0),0)))
A12: TC-11 | B12: Recherche de produits | C12: Positif | D12: B. Navigation & catalogue | E12: REQ-06 | F12: =COUNTIF('Matrice de traçabilité'!$C$3:$C$61,A12) -> 3 | G12: =IF(COUNTIFS('Matrice de traçabilité'!$C$3:$C$61,A12,'Matrice de traçabilité'!$K$3:$K$61,"KO")>0,"KO",IF(COUNTIFS('Matrice de traçabilité'!$C$3:$C$61,A12,'Matrice de traçabilité'!$K$3:$K$61,"BLOCKED")>0,"BLOCKED",IF(COUNTIFS('Matrice de traçabilité'!$C$3:$C$61,A12,'Matrice de traçabilité'!$K$3:$K$61,"NOT RUN")>0,"NOT RUN","OK"))) -> KO | H12: =IF(COUNTIFS('Matrice de traçabilité'!$C$3:$C$61,A12,'Matrice de traçabilité'!$M$3:$M$61,"<>")=0,"",INDEX('Matrice de traçabilité'!$M$3:$M$61,MATCH(1,INDEX(('Matrice de traçabilité'!$C$3:$C$61=A12)*('Matrice de traçabilité'!$M$3:$M$61<>""),0),0))) -> BUG-001 | K12: « Exécuté » = statut OK ou KO. BLOCKED et NOT RUN sont exclus du taux de réussite.
A13: TC-12 | B13: Filtres à facettes | C13: Positif | D13: B. Navigation & catalogue | E13: REQ-07 | F13: =COUNTIF('Matrice de traçabilité'!$C$3:$C$61,A13) -> 2 | G13: =IF(COUNTIFS('Matrice de traçabilité'!$C$3:$C$61,A13,'Matrice de traçabilité'!$K$3:$K$61,"KO")>0,"KO",IF(COUNTIFS('Matrice de traçabilité'!$C$3:$C$61,A13,'Matrice de traçabilité'!$K$3:$K$61,"BLOCKED")>0,"BLOCKED",IF(COUNTIFS('Matrice de traçabilité'!$C$3:$C$61,A13,'Matrice de traçabilité'!$K$3:$K$61,"NOT RUN")>0,"NOT RUN","OK"))) -> OK | H13: =IF(COUNTIFS('Matrice de traçabilité'!$C$3:$C$61,A13,'Matrice de traçabilité'!$M$3:$M$61,"<>")=0,"",INDEX('Matrice de traçabilité'!$M$3:$M$61,MATCH(1,INDEX(('Matrice de traçabilité'!$C$3:$C$61=A13)*('Matrice de traçabilité'!$M$3:$M$61<>""),0),0)))
A14: TC-13 | B14: Tri des produits | C14: Positif | D14: B. Navigation & catalogue | E14: REQ-07 | F14: =COUNTIF('Matrice de traçabilité'!$C$3:$C$61,A14) -> 2 | G14: =IF(COUNTIFS('Matrice de traçabilité'!$C$3:$C$61,A14,'Matrice de traçabilité'!$K$3:$K$61,"KO")>0,"KO",IF(COUNTIFS('Matrice de traçabilité'!$C$3:$C$61,A14,'Matrice de traçabilité'!$K$3:$K$61,"BLOCKED")>0,"BLOCKED",IF(COUNTIFS('Matrice de traçabilité'!$C$3:$C$61,A14,'Matrice de traçabilité'!$K$3:$K$61,"NOT RUN")>0,"NOT RUN","OK"))) -> OK | H14: =IF(COUNTIFS('Matrice de traçabilité'!$C$3:$C$61,A14,'Matrice de traçabilité'!$M$3:$M$61,"<>")=0,"",INDEX('Matrice de traçabilité'!$M$3:$M$61,MATCH(1,INDEX(('Matrice de traçabilité'!$C$3:$C$61=A14)*('Matrice de traçabilité'!$M$3:$M$61<>""),0),0)))
A15: TC-14 | B15: Fiche produit | C15: Positif | D15: B. Navigation & catalogue | E15: REQ-08 | F15: =COUNTIF('Matrice de traçabilité'!$C$3:$C$61,A15) -> 2 | G15: =IF(COUNTIFS('Matrice de traçabilité'!$C$3:$C$61,A15,'Matrice de traçabilité'!$K$3:$K$61,"KO")>0,"KO",IF(COUNTIFS('Matrice de traçabilité'!$C$3:$C$61,A15,'Matrice de traçabilité'!$K$3:$K$61,"BLOCKED")>0,"BLOCKED",IF(COUNTIFS('Matrice de traçabilité'!$C$3:$C$61,A15,'Matrice de traçabilité'!$K$3:$K$61,"NOT RUN")>0,"NOT RUN","OK"))) -> BLOCKED | H15: =IF(COUNTIFS('Matrice de traçabilité'!$C$3:$C$61,A15,'Matrice de traçabilité'!$M$3:$M$61,"<>")=0,"",INDEX('Matrice de traçabilité'!$M$3:$M$61,MATCH(1,INDEX(('Matrice de traçabilité'!$C$3:$C$61=A15)*('Matrice de traçabilité'!$M$3:$M$61<>""),0),0)))
A16: TC-15 | B16: Pagination des listes | C16: Positif | D16: B. Navigation & catalogue | E16: REQ-08 | F16: =COUNTIF('Matrice de traçabilité'!$C$3:$C$61,A16) -> 2 | G16: =IF(COUNTIFS('Matrice de traçabilité'!$C$3:$C$61,A16,'Matrice de traçabilité'!$K$3:$K$61,"KO")>0,"KO",IF(COUNTIFS('Matrice de traçabilité'!$C$3:$C$61,A16,'Matrice de traçabilité'!$K$3:$K$61,"BLOCKED")>0,"BLOCKED",IF(COUNTIFS('Matrice de traçabilité'!$C$3:$C$61,A16,'Matrice de traçabilité'!$K$3:$K$61,"NOT RUN")>0,"NOT RUN","OK"))) -> OK | H16: =IF(COUNTIFS('Matrice de traçabilité'!$C$3:$C$61,A16,'Matrice de traçabilité'!$M$3:$M$61,"<>")=0,"",INDEX('Matrice de traçabilité'!$M$3:$M$61,MATCH(1,INDEX(('Matrice de traçabilité'!$C$3:$C$61=A16)*('Matrice de traçabilité'!$M$3:$M$61<>""),0),0)))
A17: TC-16 | B17: Ajout d'un produit au panier | C17: Positif | D17: C. Panier | E17: REQ-09 | F17: =COUNTIF('Matrice de traçabilité'!$C$3:$C$61,A17) -> 2 | G17: =IF(COUNTIFS('Matrice de traçabilité'!$C$3:$C$61,A17,'Matrice de traçabilité'!$K$3:$K$61,"KO")>0,"KO",IF(COUNTIFS('Matrice de traçabilité'!$C$3:$C$61,A17,'Matrice de traçabilité'!$K$3:$K$61,"BLOCKED")>0,"BLOCKED",IF(COUNTIFS('Matrice de traçabilité'!$C$3:$C$61,A17,'Matrice de traçabilité'!$K$3:$K$61,"NOT RUN")>0,"NOT RUN","OK"))) -> OK | H17: =IF(COUNTIFS('Matrice de traçabilité'!$C$3:$C$61,A17,'Matrice de traçabilité'!$M$3:$M$61,"<>")=0,"",INDEX('Matrice de traçabilité'!$M$3:$M$61,MATCH(1,INDEX(('Matrice de traçabilité'!$C$3:$C$61=A17)*('Matrice de traçabilité'!$M$3:$M$61<>""),0),0)))
A18: TC-17 | B18: Modification des quantités | C18: Positif | D18: C. Panier | E18: REQ-10 | F18: =COUNTIF('Matrice de traçabilité'!$C$3:$C$61,A18) -> 2 | G18: =IF(COUNTIFS('Matrice de traçabilité'!$C$3:$C$61,A18,'Matrice de traçabilité'!$K$3:$K$61,"KO")>0,"KO",IF(COUNTIFS('Matrice de traçabilité'!$C$3:$C$61,A18,'Matrice de traçabilité'!$K$3:$K$61,"BLOCKED")>0,"BLOCKED",IF(COUNTIFS('Matrice de traçabilité'!$C$3:$C$61,A18,'Matrice de traçabilité'!$K$3:$K$61,"NOT RUN")>0,"NOT RUN","OK"))) -> KO | H18: =IF(COUNTIFS('Matrice de traçabilité'!$C$3:$C$61,A18,'Matrice de traçabilité'!$M$3:$M$61,"<>")=0,"",INDEX('Matrice de traçabilité'!$M$3:$M$61,MATCH(1,INDEX(('Matrice de traçabilité'!$C$3:$C$61=A18)*('Matrice de traçabilité'!$M$3:$M$61<>""),0),0))) -> BUG-002
A19: TC-18 | B19: Calcul du total du panier | C19: Positif | D19: C. Panier | E19: REQ-10 | F19: =COUNTIF('Matrice de traçabilité'!$C$3:$C$61,A19) -> 2 | G19: =IF(COUNTIFS('Matrice de traçabilité'!$C$3:$C$61,A19,'Matrice de traçabilité'!$K$3:$K$61,"KO")>0,"KO",IF(COUNTIFS('Matrice de traçabilité'!$C$3:$C$61,A19,'Matrice de traçabilité'!$K$3:$K$61,"BLOCKED")>0,"BLOCKED",IF(COUNTIFS('Matrice de traçabilité'!$C$3:$C$61,A19,'Matrice de traçabilité'!$K$3:$K$61,"NOT RUN")>0,"NOT RUN","OK"))) -> OK | H19: =IF(COUNTIFS('Matrice de traçabilité'!$C$3:$C$61,A19,'Matrice de traçabilité'!$M$3:$M$61,"<>")=0,"",INDEX('Matrice de traçabilité'!$M$3:$M$61,MATCH(1,INDEX(('Matrice de traçabilité'!$C$3:$C$61=A19)*('Matrice de traçabilité'!$M$3:$M$61<>""),0),0)))
A20: TC-19 | B20: Suppression d'un produit et panier vide | C20: Positif | D20: C. Panier | E20: REQ-10 | F20: =COUNTIF('Matrice de traçabilité'!$C$3:$C$61,A20) -> 2 | G20: =IF(COUNTIFS('Matrice de traçabilité'!$C$3:$C$61,A20,'Matrice de traçabilité'!$K$3:$K$61,"KO")>0,"KO",IF(COUNTIFS('Matrice de traçabilité'!$C$3:$C$61,A20,'Matrice de traçabilité'!$K$3:$K$61,"BLOCKED")>0,"BLOCKED",IF(COUNTIFS('Matrice de traçabilité'!$C$3:$C$61,A20,'Matrice de traçabilité'!$K$3:$K$61,"NOT RUN")>0,"NOT RUN","OK"))) -> OK | H20: =IF(COUNTIFS('Matrice de traçabilité'!$C$3:$C$61,A20,'Matrice de traçabilité'!$M$3:$M$61,"<>")=0,"",INDEX('Matrice de traçabilité'!$M$3:$M$61,MATCH(1,INDEX(('Matrice de traçabilité'!$C$3:$C$61=A20)*('Matrice de traçabilité'!$M$3:$M$61<>""),0),0)))
A21: TC-20 | B21: Accès au checkout et saisie de l'adresse | C21: Positif | D21: D. Commande (sans validation ni paiement) | E21: REQ-11 | F21: =COUNTIF('Matrice de traçabilité'!$C$3:$C$61,A21) -> 2 | G21: =IF(COUNTIFS('Matrice de traçabilité'!$C$3:$C$61,A21,'Matrice de traçabilité'!$K$3:$K$61,"KO")>0,"KO",IF(COUNTIFS('Matrice de traçabilité'!$C$3:$C$61,A21,'Matrice de traçabilité'!$K$3:$K$61,"BLOCKED")>0,"BLOCKED",IF(COUNTIFS('Matrice de traçabilité'!$C$3:$C$61,A21,'Matrice de traçabilité'!$K$3:$K$61,"NOT RUN")>0,"NOT RUN","OK"))) -> OK | H21: =IF(COUNTIFS('Matrice de traçabilité'!$C$3:$C$61,A21,'Matrice de traçabilité'!$M$3:$M$61,"<>")=0,"",INDEX('Matrice de traçabilité'!$M$3:$M$61,MATCH(1,INDEX(('Matrice de traçabilité'!$C$3:$C$61=A21)*('Matrice de traçabilité'!$M$3:$M$61<>""),0),0)))
A22: TC-21 | B22: Validation des champs d'adresse | C22: Négatif | D22: D. Commande (sans validation ni paiement) | E22: REQ-11 | F22: =COUNTIF('Matrice de traçabilité'!$C$3:$C$61,A22) -> 2 | G22: =IF(COUNTIFS('Matrice de traçabilité'!$C$3:$C$61,A22,'Matrice de traçabilité'!$K$3:$K$61,"KO")>0,"KO",IF(COUNTIFS('Matrice de traçabilité'!$C$3:$C$61,A22,'Matrice de traçabilité'!$K$3:$K$61,"BLOCKED")>0,"BLOCKED",IF(COUNTIFS('Matrice de traçabilité'!$C$3:$C$61,A22,'Matrice de traçabilité'!$K$3:$K$61,"NOT RUN")>0,"NOT RUN","OK"))) -> OK | H22: =IF(COUNTIFS('Matrice de traçabilité'!$C$3:$C$61,A22,'Matrice de traçabilité'!$M$3:$M$61,"<>")=0,"",INDEX('Matrice de traçabilité'!$M$3:$M$61,MATCH(1,INDEX(('Matrice de traçabilité'!$C$3:$C$61=A22)*('Matrice de traçabilité'!$M$3:$M$61<>""),0),0)))
A23: TC-22 | B23: Choix du transporteur | C23: Positif | D23: D. Commande (sans validation ni paiement) | E23: REQ-11 | F23: =COUNTIF('Matrice de traçabilité'!$C$3:$C$61,A23) -> 3 | G23: =IF(COUNTIFS('Matrice de traçabilité'!$C$3:$C$61,A23,'Matrice de traçabilité'!$K$3:$K$61,"KO")>0,"KO",IF(COUNTIFS('Matrice de traçabilité'!$C$3:$C$61,A23,'Matrice de traçabilité'!$K$3:$K$61,"BLOCKED")>0,"BLOCKED",IF(COUNTIFS('Matrice de traçabilité'!$C$3:$C$61,A23,'Matrice de traçabilité'!$K$3:$K$61,"NOT RUN")>0,"NOT RUN","OK"))) -> OK | H23: =IF(COUNTIFS('Matrice de traçabilité'!$C$3:$C$61,A23,'Matrice de traçabilité'!$M$3:$M$61,"<>")=0,"",INDEX('Matrice de traçabilité'!$M$3:$M$61,MATCH(1,INDEX(('Matrice de traçabilité'!$C$3:$C$61=A23)*('Matrice de traçabilité'!$M$3:$M$61<>""),0),0)))
A24: TC-23 | B24: Vérification du récapitulatif (sans commander) | C24: Positif | D24: D. Commande (sans validation ni paiement) | E24: REQ-11 | F24: =COUNTIF('Matrice de traçabilité'!$C$3:$C$61,A24) -> 2 | G24: =IF(COUNTIFS('Matrice de traçabilité'!$C$3:$C$61,A24,'Matrice de traçabilité'!$K$3:$K$61,"KO")>0,"KO",IF(COUNTIFS('Matrice de traçabilité'!$C$3:$C$61,A24,'Matrice de traçabilité'!$K$3:$K$61,"BLOCKED")>0,"BLOCKED",IF(COUNTIFS('Matrice de traçabilité'!$C$3:$C$61,A24,'Matrice de traçabilité'!$K$3:$K$61,"NOT RUN")>0,"NOT RUN","OK"))) -> OK | H24: =IF(COUNTIFS('Matrice de traçabilité'!$C$3:$C$61,A24,'Matrice de traçabilité'!$M$3:$M$61,"<>")=0,"",INDEX('Matrice de traçabilité'!$M$3:$M$61,MATCH(1,INDEX(('Matrice de traçabilité'!$C$3:$C$61=A24)*('Matrice de traçabilité'!$M$3:$M$61<>""),0),0)))
... A28: TC-27 | B28: Historique des commandes | C28: Positif | D28: E. Compte client | E28: REQ-12 | F28: =COUNTIF('Matrice de traçabilité'!$C$3:$C$61,A28) -> 1 | G28: =IF(COUNTIFS('Matrice de traçabilité'!$C$3:$C$61,A28,'Matrice de traçabilité'!$K$3:$K$61,"KO")>0,"KO",IF(COUNTIFS('Matrice de traçabilité'!$C$3:$C$61,A28,'Matrice de traçabilité'!$K$3:$K$61,"BLOCKED")>0,"BLOCKED",IF(COUNTIFS('Matrice de traçabilité'!$C$3:$C$61,A28,'Matrice de traçabilité'!$K$3:$K$61,"NOT RUN")>0,"NOT RUN","OK"))) -> OK | H28: =IF(COUNTIFS('Matrice de traçabilité'!$C$3:$C$61,A28,'Matrice de traçabilité'!$M$3:$M$61,"<>")=0,"",INDEX('Matrice de traçabilité'!$M$3:$M$61,MATCH(1,INDEX(('Matrice de traçabilité'!$C$3:$C$61=A28)*('Matrice de traçabilité'!$M$3:$M$61<>""),0),0)))
